<?xml version="1.0" ?>
<sdf version="1.7">
    <world name="project_world">
        <physics name="1ms" type="ignored">
            <max_step_size>0.001</max_step_size>
            <real_time_factor>1.0</real_time_factor>
        </physics>
        <plugin
            filename="libignition-gazebo-physics-system.so"
            name="ignition::gazebo::systems::Physics">
        </plugin>
        <plugin
            filename="libignition-gazebo-user-commands-system.so"
            name="ignition::gazebo::systems::UserCommands">
        </plugin>
        <plugin
            filename="libignition-gazebo-scene-broadcaster-system.so"
            name="ignition::gazebo::systems::SceneBroadcaster">
        </plugin>
        <plugin filename="libignition-gazebo-imu-system.so"
                name="ignition::gazebo::systems::Imu">
        </plugin>
        <plugin
          filename="libignition-gazebo-sensors-system.so"
          name="ignition::gazebo::systems::Sensors">
          <render_engine>ogre2</render_engine>
        </plugin>

        <gui fullscreen="0">
            <plugin filename="GzScene3D" name="3D View">
                <ignition-gui>
                <title>3D View</title>
                <property type="bool" key="showTitleBar">false</property>
                <property type="string" key="state">docked</property>
                </ignition-gui>
                <engine>ogre2</engine>
                <scene>scene</scene>
                <ambient_light>0.4 0.4 0.4</ambient_light>
                <background_color>0.8 0.8 0.8</background_color>
            </plugin>

            <plugin filename="WorldControl" name="World control">
                <ignition-gui>
                <title>World control</title>
                <property type="bool" key="showTitleBar">false</property>
                <property type="bool" key="resizable">false</property>
                <property type="double" key="height">72</property>
                <property type="double" key="width">121</property>
                <property type="double" key="z">1</property>
                <property type="string" key="state">floating</property>
                <anchors target="3D View">
                    <line own="left" target="left"/>
                    <line own="bottom" target="bottom"/>
                </anchors>
                </ignition-gui>
                <play_pause>true</play_pause>
                <step>true</step>
                <start_paused>true</start_paused>
                <service>/world/project_world/control</service>
                <stats_topic>/world/project_world/stats</stats_topic>
            </plugin>

            <plugin filename="WorldStats" name="World stats">
                <ignition-gui>
                <title>World stats</title>
                <property type="bool" key="showTitleBar">false</property>
                <property type="bool" key="resizable">false</property>
                <property type="double" key="height">110</property>
                <property type="double" key="width">290</property>
                <property type="double" key="z">1</property>
                <property type="string" key="state">floating</property>
                <anchors target="3D View">
                    <line own="right" target="right"/>
                    <line own="bottom" target="bottom"/>
                </anchors>
                </ignition-gui>
                <sim_time>true</sim_time>
                <real_time>true</real_time>
                <real_time_factor>true</real_time_factor>
                <iterations>true</iterations>
                <topic>/world/project_world/stats</topic>
            </plugin>

            <plugin filename="EntityTree" name="Entity tree">
            </plugin>
        </gui>

        <light type="directional" name="sun">
            <cast_shadows>true</cast_shadows>
            <pose>0 0 10 0 0 0</pose>
            <diffuse>0.8 0.8 0.8 1</diffuse>
            <specular>0.2 0.2 0.2 1</specular>
            <attenuation>
                <range>1000</range>
                <constant>0.9</constant>
                <linear>0.01</linear>
                <quadratic>0.001</quadratic>
            </attenuation>
            <direction>-0.5 0.1 -0.9</direction>
        </light>

        <model name="ground_plane">
            <static>true</static>
            <link name="link">
                <collision name="collision">
                <geometry>
                    <plane>
                    <normal>0 0 1</normal>
                    </plane>
                </geometry>
                </collision>
                <visual name="visual">
                <geometry>
                    <plane>
                    <normal>0 0 1</normal>
                    <size>100 100</size>
                    </plane>
                </geometry>
                <material>
                    <ambient>0.8 0.8 0.8 1</ambient>
                    <diffuse>0.8 0.8 0.8 1</diffuse>
                    <specular>0.8 0.8 0.8 1</specular>
                </material>
                </visual>
            </link>
        </model>

        <!-- Generated Landmarks (10 total) -->

        <model name='landmark_0_color_000'>
            <static>true</static>
            <pose>-1.284 9.280 0.500 0 0 0</pose>
            <link name='link'>
                <visual name='visual'>
                    <geometry>
                        <cylinder>
                            <radius>0.2</radius>
                            <length>1.0</length>
                        </cylinder>
                    </geometry>
                    <material>
                        <ambient>1.000 0.000 0.000 1</ambient>
                        <diffuse>1.000 0.000 0.000 1</diffuse>
                    </material>
                </visual>
                <collision name='collision'>
                    <geometry>
                        <cylinder>
                            <radius>0.2</radius>
                            <length>1.0</length>
                        </cylinder>
                    </geometry>
                </collision>
            </link>
        </model>

        <model name='landmark_1_color_018'>
            <static>true</static>
            <pose>6.726 3.802 0.500 0 0 0</pose>
            <link name='link'>
                <visual name='visual'>
                    <geometry>
                        <cylinder>
                            <radius>0.2</radius>
                            <length>1.0</length>
                        </cylinder>
                    </geometry>
                    <material>
                        <ambient>1.000 0.600 0.000 1</ambient>
                        <diffuse>1.000 0.600 0.000 1</diffuse>
                    </material>
                </visual>
                <collision name='collision'>
                    <geometry>
                        <cylinder>
                            <radius>0.2</radius>
                            <length>1.0</length>
                        </cylinder>
                    </geometry>
                </collision>
            </link>
        </model>

        <model name='landmark_2_color_036'>
            <static>true</static>
            <pose>3.703 1.809 0.500 0 0 0</pose>
            <link name='link'>
                <visual name='visual'>
                    <geometry>
                        <cylinder>
                            <radius>0.2</radius>
                            <length>1.0</length>
                        </cylinder>
                    </geometry>
                    <material>
                        <ambient>1.000 1.000 0.000 1</ambient>
                        <diffuse>1.000 1.000 0.000 1</diffuse>
                    </material>
                </visual>
                <collision name='collision'>
                    <geometry>
                        <cylinder>
                            <radius>0.2</radius>
                            <length>1.0</length>
                        </cylinder>
                    </geometry>
                </collision>
            </link>
        </model>

        <model name='landmark_3_color_054'>
            <static>true</static>
            <pose>-1.118 5.175 0.500 0 0 0</pose>
            <link name='link'>
                <visual name='visual'>
                    <geometry>
                        <cylinder>
                            <radius>0.2</radius>
                            <length>1.0</length>
                        </cylinder>
                    </geometry>
                    <material>
                        <ambient>0.400 1.000 0.000 1</ambient>
                        <diffuse>0.400 1.000 0.000 1</diffuse>
                    </material>
                </visual>
                <collision name='collision'>
                    <geometry>
                        <cylinder>
                            <radius>0.2</radius>
                            <length>1.0</length>
                        </cylinder>
                    </geometry>
                </collision>
            </link>
        </model>

        <model name='landmark_4_color_072'>
            <static>true</static>
            <pose>-4.557 11.293 0.500 0 0 0</pose>
            <link name='link'>
                <visual name='visual'>
                    <geometry>
                        <cylinder>
                            <radius>0.2</radius>
                            <length>1.0</length>
                        </cylinder>
                    </geometry>
                    <material>
                        <ambient>0.000 1.000 0.200 1</ambient>
                        <diffuse>0.000 1.000 0.200 1</diffuse>
                    </material>
                </visual>
                <collision name='collision'>
                    <geometry>
                        <cylinder>
                            <radius>0.2</radius>
                            <length>1.0</length>
                        </cylinder>
                    </geometry>
                </collision>
            </link>
        </model>

        <model name='landmark_5_color_090'>
            <static>true</static>
            <pose>10.601 2.423 0.500 0 0 0</pose>
            <link name='link'>
                <visual name='visual'>
                    <geometry>
                        <cylinder>
                            <radius>0.2</radius>
                            <length>1.0</length>
                        </cylinder>
                    </geometry>
                    <material>
                        <ambient>0.000 1.000 1.000 1</ambient>
                        <diffuse>0.000 1.000 1.000 1</diffuse>
                    </material>
                </visual>
                <collision name='collision'>
                    <geometry>
                        <cylinder>
                            <radius>0.2</radius>
                            <length>1.0</length>
                        </cylinder>
                    </geometry>
                </collision>
            </link>
        </model>

        <model name='landmark_6_color_108'>
            <static>true</static>
            <pose>8.428 9.561 0.500 0 0 0</pose>
            <link name='link'>
                <visual name='visual'>
                    <geometry>
                        <cylinder>
                            <radius>0.2</radius>
                            <length>1.0</length>
                        </cylinder>
                    </geometry>
                    <material>
                        <ambient>0.000 0.400 1.000 1</ambient>
                        <diffuse>0.000 0.400 1.000 1</diffuse>
                    </material>
                </visual>
                <collision name='collision'>
                    <geometry>
                        <cylinder>
                            <radius>0.2</radius>
                            <length>1.0</length>
                        </cylinder>
                    </geometry>
                </collision>
            </link>
        </model>

        <model name='landmark_7_color_126'>
            <static>true</static>
            <pose>-0.517 -6.300 0.500 0 0 0</pose>
            <link name='link'>
                <visual name='visual'>
                    <geometry>
                        <cylinder>
                            <radius>0.2</radius>
                            <length>1.0</length>
                        </cylinder>
                    </geometry>
                    <material>
                        <ambient>0.200 0.000 1.000 1</ambient>
                        <diffuse>0.200 0.000 1.000 1</diffuse>
                    </material>
                </visual>
                <collision name='collision'>
                    <geometry>
                        <cylinder>
                            <radius>0.2</radius>
                            <length>1.0</length>
                        </cylinder>
                    </geometry>
                </collision>
            </link>
        </model>

        <model name='landmark_8_color_144'>
            <static>true</static>
            <pose>6.872 -9.703 0.500 0 0 0</pose>
            <link name='link'>
                <visual name='visual'>
                    <geometry>
                        <cylinder>
                            <radius>0.2</radius>
                            <length>1.0</length>
                        </cylinder>
                    </geometry>
                    <material>
                        <ambient>0.800 0.000 1.000 1</ambient>
                        <diffuse>0.800 0.000 1.000 1</diffuse>
                    </material>
                </visual>
                <collision name='collision'>
                    <geometry>
                        <cylinder>
                            <radius>0.2</radius>
                            <length>1.0</length>
                        </cylinder>
                    </geometry>
                </collision>
            </link>
        </model>

        <model name='landmark_9_color_162'>
            <static>true</static>
            <pose>-4.335 -13.472 0.500 0 0 0</pose>
            <link name='link'>
                <visual name='visual'>
                    <geometry>
                        <cylinder>
                            <radius>0.2</radius>
                            <length>1.0</length>
                        </cylinder>
                    </geometry>
                    <material>
                        <ambient>1.000 0.000 0.600 1</ambient>
                        <diffuse>1.000 0.000 0.600 1</diffuse>
                    </material>
                </visual>
                <collision name='collision'>
                    <geometry>
                        <cylinder>
                            <radius>0.2</radius>
                            <length>1.0</length>
                        </cylinder>
                    </geometry>
                </collision>
            </link>
        </model>


        <model name='turtlebot3_waffle' canonical_link='base_footprint'>
            <pose>0 0 0 0 0 0</pose>

            <link name='base_footprint'>
                <pose>0 0 0 0 0 0</pose>
                <inertial>
                    <mass>0.001</mass>
                    <inertia>
                        <ixx>0.0001</ixx><ixy>0</ixy><ixz>0</ixz>
                        <iyy>0.0001</iyy><iyz>0</iyz><izz>0.0001</izz>
                    </inertia>
                </inertial>
            </link>

            <link name='base_link'>
                <pose relative_to='base_footprint'>0 0 0.010 0 0 0</pose>
                <inertial>
                    <mass>1.3729096</mass>
                    <inertia>
                        <ixx>0.0117754808</ixx><ixy>0</ixy><ixz>0</ixz>
                        <iyy>0.0117754808</iyy><iyz>0</iyz><izz>0.0184</izz>
                    </inertia>
                </inertial>
                <!-- Main body - circular base -->
                <visual name='base_visual'>
                    <pose>0 0 0.047 0 0 0</pose>
                    <geometry>
                        <cylinder><radius>0.133</radius><length>0.094</length></cylinder>
                    </geometry>
                    <material>
                        <ambient>0.1 0.1 0.1 1</ambient>
                        <diffuse>0.1 0.1 0.1 1</diffuse>
                    </material>
                </visual>
                <!-- Top plate -->
                <visual name='top_plate_visual'>
                    <pose>0 0 0.12 0 0 0</pose>
                    <geometry>
                        <cylinder><radius>0.133</radius><length>0.02</length></cylinder>
                    </geometry>
                    <material>
                        <ambient>0.3 0.3 0.3 1</ambient>
                        <diffuse>0.3 0.3 0.3 1</diffuse>
                    </material>
                </visual>
                <collision name='base_collision'>
                    <pose>0 0 0.047 0 0 0</pose>
                    <geometry>
                        <cylinder><radius>0.133</radius><length>0.094</length></cylinder>
                    </geometry>
                </collision>

                <!-- IMU Sensor -->
                <sensor name='imu_sensor' type='imu'>
                    <always_on>true</always_on>
                    <update_rate>50</update_rate>
                    <topic>imu</topic>
                    <imu>
                        <enable_orientation>false</enable_orientation>
                        <angular_velocity>
                            <x><noise type='gaussian'><mean>0</mean><stddev>0.0</stddev></noise></x>
                            <y><noise type='gaussian'><mean>0</mean><stddev>0.0</stddev></noise></y>
                            <z><noise type='gaussian'><mean>0</mean><stddev>0.0</stddev></noise></z>
                        </angular_velocity>
                        <linear_acceleration>
                            <x><noise type='gaussian'><mean>0</mean><stddev>0.0</stddev></noise></x>
                            <y><noise type='gaussian'><mean>0</mean><stddev>0.0</stddev></noise></y>
                            <z><noise type='gaussian'><mean>0</mean><stddev>0.0</stddev></noise></z>
                        </linear_acceleration>
                    </imu>
                </sensor>
            </link>

            <!-- Camera Link -->
            <link name='camera_link'>
                <pose relative_to='base_link'>0.12 0 0.20 0 -0.15 0</pose>
                <inertial>
                    <mass>0.035</mass>
                    <inertia>
                        <ixx>0.00001</ixx><ixy>0</ixy><ixz>0</ixz>
                        <iyy>0.00001</iyy><iyz>0</iyz><izz>0.00001</izz>
                    </inertia>
                </inertial>
                <visual name='camera_visual'>
                    <geometry>
                        <box><size>0.02 0.06 0.02</size></box>
                    </geometry>
                    <material>
                        <ambient>0.0 0.0 0.8 1</ambient>
                        <diffuse>0.0 0.0 0.8 1</diffuse>
                    </material>
                </visual>
                <sensor name='camera' type='camera'>
                    <always_on>true</always_on>
                    <update_rate>10</update_rate>
                    <topic>camera/image</topic>
                    <camera>
                        <horizontal_fov>1.085</horizontal_fov>
                        <image>
                            <width>1280</width>
                            <height>720</height>
                            <format>R8G8B8</format>
                        </image>
                        <clip><near>0.1</near><far>100</far></clip>
                    </camera>
                </sensor>
            </link>

            <!-- Left Wheel -->
            <link name='wheel_left_link'>
                <pose relative_to='base_link'>0 0.144 0.033 -1.5708 0 0</pose>
                <inertial>
                    <mass>0.1</mass>
                    <inertia>
                        <ixx>0.0001</ixx><ixy>0</ixy><ixz>0</ixz>
                        <iyy>0.0001</iyy><iyz>0</iyz><izz>0.0001</izz>
                    </inertia>
                </inertial>
                <visual name='wheel_left_visual'>
                    <geometry>
                        <cylinder><radius>0.033</radius><length>0.018</length></cylinder>
                    </geometry>
                    <material>
                        <ambient>0.2 0.2 0.2 1</ambient>
                        <diffuse>0.2 0.2 0.2 1</diffuse>
                    </material>
                </visual>
                <collision name='wheel_left_collision'>
                    <geometry>
                        <cylinder><radius>0.033</radius><length>0.018</length></cylinder>
                    </geometry>
                    <surface>
                        <friction>
                            <ode><mu>1.0</mu><mu2>1.0</mu2></ode>
                        </friction>
                    </surface>
                </collision>
            </link>

            <!-- Right Wheel -->
            <link name='wheel_right_link'>
                <pose relative_to='base_link'>0 -0.144 0.033 -1.5708 0 0</pose>
                <inertial>
                    <mass>0.1</mass>
                    <inertia>
                        <ixx>0.0001</ixx><ixy>0</ixy><ixz>0</ixz>
                        <iyy>0.0001</iyy><iyz>0</iyz><izz>0.0001</izz>
                    </inertia>
                </inertial>
                <visual name='wheel_right_visual'>
                    <geometry>
                        <cylinder><radius>0.033</radius><length>0.018</length></cylinder>
                    </geometry>
                    <material>
                        <ambient>0.2 0.2 0.2 1</ambient>
                        <diffuse>0.2 0.2 0.2 1</diffuse>
                    </material>
                </visual>
                <collision name='wheel_right_collision'>
                    <geometry>
                        <cylinder><radius>0.033</radius><length>0.018</length></cylinder>
                    </geometry>
                    <surface>
                        <friction>
                            <ode><mu>1.0</mu><mu2>1.0</mu2></ode>
                        </friction>
                    </surface>
                </collision>
            </link>

            <!-- Caster Wheels -->
            <link name='caster_back_left_link'>
                <pose relative_to='base_link'>-0.090 0.047 0.005 0 0 0</pose>
                <inertial>
                    <mass>0.01</mass>
                    <inertia>
                        <ixx>0.00001</ixx><ixy>0</ixy><ixz>0</ixz>
                        <iyy>0.00001</iyy><iyz>0</iyz><izz>0.00001</izz>
                    </inertia>
                </inertial>
                <visual name='caster_visual'>
                    <geometry><sphere><radius>0.005</radius></sphere></geometry>
                    <material>
                        <ambient>0.2 0.2 0.2 1</ambient>
                        <diffuse>0.2 0.2 0.2 1</diffuse>
                    </material>
                </visual>
                <collision name='caster_collision'>
                    <geometry><sphere><radius>0.005</radius></sphere></geometry>
                    <surface>
                        <friction><ode><mu>0.0</mu><mu2>0.0</mu2></ode></friction>
                    </surface>
                </collision>
            </link>

            <link name='caster_back_right_link'>
                <pose relative_to='base_link'>-0.090 -0.047 0.005 0 0 0</pose>
                <inertial>
                    <mass>0.01</mass>
                    <inertia>
                        <ixx>0.00001</ixx><ixy>0</ixy><ixz>0</ixz>
                        <iyy>0.00001</iyy><iyz>0</iyz><izz>0.00001</izz>
                    </inertia>
                </inertial>
                <visual name='caster_visual'>
                    <geometry><sphere><radius>0.005</radius></sphere></geometry>
                    <material>
                        <ambient>0.2 0.2 0.2 1</ambient>
                        <diffuse>0.2 0.2 0.2 1</diffuse>
                    </material>
                </visual>
                <collision name='caster_collision'>
                    <geometry><sphere><radius>0.005</radius></sphere></geometry>
                    <surface>
                        <friction><ode><mu>0.0</mu><mu2>0.0</mu2></ode></friction>
                    </surface>
                </collision>
            </link>

            <!-- Joints -->
            <joint name='base_joint' type='fixed'>
                <parent>base_footprint</parent>
                <child>base_link</child>
            </joint>

            <joint name='camera_joint' type='fixed'>
                <parent>base_link</parent>
                <child>camera_link</child>
            </joint>

            <joint name='wheel_left_joint' type='revolute'>
                <parent>base_link</parent>
                <child>wheel_left_link</child>
                <axis>
                    <xyz>0 0 1</xyz>
                    <limit><lower>-1.79769e+308</lower><upper>1.79769e+308</upper></limit>
                </axis>
            </joint>

            <joint name='wheel_right_joint' type='revolute'>
                <parent>base_link</parent>
                <child>wheel_right_link</child>
                <axis>
                    <xyz>0 0 1</xyz>
                    <limit><lower>-1.79769e+308</lower><upper>1.79769e+308</upper></limit>
                </axis>
            </joint>

            <joint name='caster_back_left_joint' type='ball'>
                <parent>base_link</parent>
                <child>caster_back_left_link</child>
            </joint>

            <joint name='caster_back_right_joint' type='ball'>
                <parent>base_link</parent>
                <child>caster_back_right_link</child>
            </joint>

            <!-- Diff Drive Plugin -->
            <plugin filename='libignition-gazebo-diff-drive-system.so' name='ignition::gazebo::systems::DiffDrive'>
                <left_joint>wheel_left_joint</left_joint>
                <right_joint>wheel_right_joint</right_joint>
                <wheel_separation>0.287</wheel_separation>
                <wheel_radius>0.033</wheel_radius>
                <odom_publish_frequency>30</odom_publish_frequency>
                <topic>cmd_vel</topic>
                <odom_topic>odom</odom_topic>
                <frame_id>odom</frame_id>
                <child_frame_id>turtlebot3_waffle/base_footprint</child_frame_id>  <!-- ADD MODEL NAME PREFIX -->
            </plugin>
        </model>

    </world>
</sdf>
